2025-10-04 09:36:24,866 : INFO : root : Loading config.
2025-10-04 09:36:24,871 : INFO : YamlMultifileConfigLoader : Machine config file #1: config.yaml
2025-10-04 09:36:24,871 : INFO : ConfigProcessor : Loading config from cache: C:\Users\richa\AppData\Local\Temp\bad76953a596b8c99f832e0e98026c3b.mpf_cache
2025-10-04 09:36:24,961 : INFO : ConfigProcessor : Loading config from cache: C:\Users\richa\AppData\Local\Temp\77a998d318c788df5647a1900cedfc56.mpf_cache
2025-10-04 09:36:24,961 : INFO : ConfigProcessor : Loading config from cache: C:\Users\richa\AppData\Local\Temp\9c8dea79ca4d15ee886340e992e8cb9d.mpf_cache
2025-10-04 09:36:24,962 : WARNING : ConfigProcessor : Config file in cache changed: C:\Users\richa\ttp5\modes\base\config\base.yaml
2025-10-04 09:36:24,962 : INFO : ConfigProcessor : Loading config from file C:\Users\richa\ttp5\modes\base\config\base.yaml.
2025-10-04 09:36:24,976 : INFO : ConfigProcessor : Loading config: C:\Users\richa\ttp5\modes\base\config\base.yaml
2025-10-04 09:36:24,977 : INFO : ConfigProcessor : Config file cache created: C:\Users\richa\AppData\Local\Temp\8ddee2e87a4f178751335e99da00e9c4.mpf_cache
2025-10-04 09:36:24,978 : INFO : ConfigProcessor : Loading config from cache: C:\Users\richa\AppData\Local\Temp\16d594341c3fbe91b1b6d496c05a6fb0.mpf_cache
2025-10-04 09:36:24,979 : INFO : ConfigProcessor : Loading config from cache: C:\Users\richa\AppData\Local\Temp\9ea1b14cb2b1cce5e8bf981a1ff8cfc5.mpf_cache
2025-10-04 09:36:24,979 : INFO : ConfigProcessor : Loading config from cache: C:\Users\richa\AppData\Local\Temp\6cbce11faef0ddcfeddb2a5b8dbeb4ae.mpf_cache
2025-10-04 09:36:24,980 : INFO : Machine : Mission Pinball Framework Core Engine v0.57.0.dev39
2025-10-04 09:36:24,980 : INFO : Machine : Command line arguments: {'no_load_cache': False, 'create_config_cache': True, 'bcp': True, 'configfile': ['config.yaml'], 'force_assets_load': False, 'jsonlogging': False, 'logfile': 'logs\\2025-10-04-09-36-24-mpf-DESKTOP-RK7BE5M.log', 'pause': False, 'production': False, 'text_ui': True, 'loglevel': 15, 'consoleloglevel': 20, 'force_platform': None, 'syslog_address': None, 'mc_file_name': None, 'no_sound': False}
2025-10-04 09:36:24,980 : INFO : Machine : MPF path: C:\Users\richa\mpfvirtual4\lib\site-packages\mpf
2025-10-04 09:36:24,980 : INFO : Machine : Machine path: C:\Users\richa\ttp5
2025-10-04 09:36:24,980 : INFO : Machine : Platform: win32
2025-10-04 09:36:24,980 : INFO : Machine : Python executable location: C:\Users\richa\mpfvirtual4\Scripts\python.exe
2025-10-04 09:36:24,980 : INFO : Machine : Python version: 3.9.13 (64-bit)
2025-10-04 09:36:24,982 : INFO : Machine : Initializing MPF...
2025-10-04 09:36:25,510 : INFO : EventManager : Event: ======'machine_var_credits_string'====== Args={'value': 'FREE PLAY', 'prev_value': None, 'change': True}
2025-10-04 09:36:25,567 : INFO : EventManager : Event: ======'machine_var_master_volume'====== Args={'value': 0.5, 'prev_value': None, 'change': True}
2025-10-04 09:36:25,567 : INFO : EventManager : Event: ======'machine_var_player1_score'====== Args={'value': 10994, 'prev_value': None, 'change': True}
2025-10-04 09:36:25,568 : INFO : EventManager : Event: ======'machine_var_mpf_version'====== Args={'value': 'Mission Pinball Framework v0.57.0.dev39', 'prev_value': None, 'change': True}
2025-10-04 09:36:25,568 : INFO : EventManager : Event: ======'machine_var_mpf_extended_version'====== Args={'value': 'Mission Pinball Framework v0.57.0.dev39, Config version:6, Show version: 6, BCP version:1.1', 'prev_value': None, 'change': True}
2025-10-04 09:36:25,568 : INFO : EventManager : Event: ======'machine_var_python_version'====== Args={'value': '3.9.13', 'prev_value': None, 'change': True}
2025-10-04 09:36:25,577 : INFO : EventManager : Event: ======'machine_var_platform'====== Args={'value': 'Windows-10-10.0.19045-SP0', 'prev_value': None, 'change': True}
2025-10-04 09:36:25,577 : INFO : EventManager : Event: ======'machine_var_platform_system'====== Args={'value': 'Windows', 'prev_value': None, 'change': True}
2025-10-04 09:36:25,577 : INFO : EventManager : Event: ======'machine_var_platform_release'====== Args={'value': '10', 'prev_value': None, 'change': True}
2025-10-04 09:36:25,577 : INFO : EventManager : Event: ======'machine_var_platform_version'====== Args={'value': '10.0.19045', 'prev_value': None, 'change': True}
2025-10-04 09:36:25,578 : INFO : EventManager : Event: ======'machine_var_platform_machine'====== Args={'value': 'AMD64', 'prev_value': None, 'change': True}
2025-10-04 09:36:25,578 : INFO : EventManager : Event: ======'init_phase_1'====== Args={}
2025-10-04 09:36:25,592 : ERROR : asyncio : Exception in callback EventManager._async_handler_done(<QueuedEvent>)(<Task finishe...alue to ms.')>) at C:\Users\richa\mpfvirtual4\lib\site-packages\mpf\core\events.py:124
handle: <Handle EventManager._async_handler_done(<QueuedEvent>)(<Task finishe...alue to ms.')>) at C:\Users\richa\mpfvirtual4\lib\site-packages\mpf\core\events.py:124>
Traceback (most recent call last):
  File "C:\Users\richa\mpfvirtual4\lib\site-packages\mpf\core\config_validator.py", line 577, in _validate_type_ms
    return Util.string_to_ms(item)
  File "C:\Users\richa\mpfvirtual4\lib\site-packages\mpf\core\utility_functions.py", line 612, in string_to_ms
    return int(time_string)
ValueError: invalid literal for int() with base 10: 'ROLLOVER_LANES_LIT_COMPLETE'

During handling of the above exception, another exception occurred:

Traceback (most recent call last):
  File "C:\Users\richa\AppData\Local\Programs\Python\Python39\lib\asyncio\events.py", line 80, in _run
    self._context.run(self._callback, *self._args)
  File "C:\Users\richa\mpfvirtual4\lib\site-packages\mpf\core\events.py", line 127, in _async_handler_done
    future.result()
  File "C:\Users\richa\mpfvirtual4\lib\site-packages\mpf\core\device_manager.py", line 89, in _load_device_modules
    await self.machine.mode_controller.load_mode_devices()
  File "C:\Users\richa\mpfvirtual4\lib\site-packages\mpf\core\mode_controller.py", line 86, in load_mode_devices
    await mode.load_mode_devices()
  File "C:\Users\richa\mpfvirtual4\lib\site-packages\mpf\core\mode.py", line 438, in load_mode_devices
    settings = device.validate_and_parse_config(settings, True, "mode:" + self.name)
  File "C:\Users\richa\mpfvirtual4\lib\site-packages\mpf\core\device.py", line 108, in validate_and_parse_config
    self.machine.config_validator.validate_config(
  File "C:\Users\richa\mpfvirtual4\lib\site-packages\mpf\core\config_validator.py", line 164, in validate_config
    return self._validate_config(config_spec, source, base_spec=base_spec, add_missing_keys=add_missing_keys,
  File "C:\Users\richa\mpfvirtual4\lib\site-packages\mpf\core\config_validator.py", line 205, in _validate_config
    processed_config[k] = self.validate_config_item(
  File "C:\Users\richa\mpfvirtual4\lib\site-packages\mpf\core\config_validator.py", line 273, in validate_config_item
    return self._validate_dict(item_type, validation, validation_failure_info, item)
  File "C:\Users\richa\mpfvirtual4\lib\site-packages\mpf\core\config_validator.py", line 304, in _validate_dict
    self.validate_item(v, validators[1], ValidationPath(validation_failure_info, k)))
  File "C:\Users\richa\mpfvirtual4\lib\site-packages\mpf\core\config_validator.py", line 685, in validate_item
    return self.validator_list[validator](item, validation_failure_info=validation_failure_info)
  File "C:\Users\richa\mpfvirtual4\lib\site-packages\mpf\core\config_validator.py", line 579, in _validate_type_ms
    self.validation_error(item, validation_failure_info, "Cannot convert value to ms.", 11)
  File "C:\Users\richa\mpfvirtual4\lib\site-packages\mpf\core\config_validator.py", line 700, in validation_error
    raise ConfigFileError("Config validation error: Entry {} = \"{}\" is not valid. {}".format(
mpf.exceptions.config_file_error.ConfigFileError: Config File Error in ConfigValidator: Config validation error: Entry mode:base:shot_groups:rollover_lanes:reset_events:rollover_lanes_lit_complete = "rollover_lanes_lit_complete" is not valid. Cannot convert value to ms. Error Code: CFE-ConfigValidator-11 (https://missionpinball.org/logs)
2025-10-04 09:36:25,609 : INFO : Machine : Starting the main run loop.
2025-10-04 09:36:25,616 : INFO : Machine : Shutting down...
2025-10-04 09:36:25,617 : INFO : EventManager : Event: ======'shutdown'====== Args={}
2025-10-04 09:36:26,620 : ERROR : Machine : Runtime Exception
Traceback (most recent call last):
  File "C:\Users\richa\mpfvirtual4\lib\site-packages\mpf\core\config_validator.py", line 577, in _validate_type_ms
    return Util.string_to_ms(item)
  File "C:\Users\richa\mpfvirtual4\lib\site-packages\mpf\core\utility_functions.py", line 612, in string_to_ms
    return int(time_string)
ValueError: invalid literal for int() with base 10: 'ROLLOVER_LANES_LIT_COMPLETE'

During handling of the above exception, another exception occurred:

Traceback (most recent call last):
  File "C:\Users\richa\mpfvirtual4\lib\site-packages\mpf\core\machine.py", line 788, in _run_loop
    raise self._exception['exception']
  File "C:\Users\richa\AppData\Local\Programs\Python\Python39\lib\asyncio\events.py", line 80, in _run
    self._context.run(self._callback, *self._args)
  File "C:\Users\richa\mpfvirtual4\lib\site-packages\mpf\core\events.py", line 127, in _async_handler_done
    future.result()
  File "C:\Users\richa\mpfvirtual4\lib\site-packages\mpf\core\device_manager.py", line 89, in _load_device_modules
    await self.machine.mode_controller.load_mode_devices()
  File "C:\Users\richa\mpfvirtual4\lib\site-packages\mpf\core\mode_controller.py", line 86, in load_mode_devices
    await mode.load_mode_devices()
  File "C:\Users\richa\mpfvirtual4\lib\site-packages\mpf\core\mode.py", line 438, in load_mode_devices
    settings = device.validate_and_parse_config(settings, True, "mode:" + self.name)
  File "C:\Users\richa\mpfvirtual4\lib\site-packages\mpf\core\device.py", line 108, in validate_and_parse_config
    self.machine.config_validator.validate_config(
  File "C:\Users\richa\mpfvirtual4\lib\site-packages\mpf\core\config_validator.py", line 164, in validate_config
    return self._validate_config(config_spec, source, base_spec=base_spec, add_missing_keys=add_missing_keys,
  File "C:\Users\richa\mpfvirtual4\lib\site-packages\mpf\core\config_validator.py", line 205, in _validate_config
    processed_config[k] = self.validate_config_item(
  File "C:\Users\richa\mpfvirtual4\lib\site-packages\mpf\core\config_validator.py", line 273, in validate_config_item
    return self._validate_dict(item_type, validation, validation_failure_info, item)
  File "C:\Users\richa\mpfvirtual4\lib\site-packages\mpf\core\config_validator.py", line 304, in _validate_dict
    self.validate_item(v, validators[1], ValidationPath(validation_failure_info, k)))
  File "C:\Users\richa\mpfvirtual4\lib\site-packages\mpf\core\config_validator.py", line 685, in validate_item
    return self.validator_list[validator](item, validation_failure_info=validation_failure_info)
  File "C:\Users\richa\mpfvirtual4\lib\site-packages\mpf\core\config_validator.py", line 579, in _validate_type_ms
    self.validation_error(item, validation_failure_info, "Cannot convert value to ms.", 11)
  File "C:\Users\richa\mpfvirtual4\lib\site-packages\mpf\core\config_validator.py", line 700, in validation_error
    raise ConfigFileError("Config validation error: Entry {} = \"{}\" is not valid. {}".format(
mpf.exceptions.config_file_error.ConfigFileError: Config File Error in ConfigValidator: Config validation error: Entry mode:base:shot_groups:rollover_lanes:reset_events:rollover_lanes_lit_complete = "rollover_lanes_lit_complete" is not valid. Cannot convert value to ms. Error Code: CFE-ConfigValidator-11 (https://missionpinball.org/logs)
2025-10-04 09:36:30,656 : ERROR : root : 
Traceback (most recent call last):
  File "C:\Users\richa\mpfvirtual4\lib\site-packages\mpf\core\config_validator.py", line 577, in _validate_type_ms
    return Util.string_to_ms(item)
  File "C:\Users\richa\mpfvirtual4\lib\site-packages\mpf\core\utility_functions.py", line 612, in string_to_ms
    return int(time_string)
ValueError: invalid literal for int() with base 10: 'ROLLOVER_LANES_LIT_COMPLETE'

During handling of the above exception, another exception occurred:

Traceback (most recent call last):
  File "C:\Users\richa\mpfvirtual4\lib\site-packages\mpf\core\machine.py", line 788, in _run_loop
    raise self._exception['exception']
  File "C:\Users\richa\AppData\Local\Programs\Python\Python39\lib\asyncio\events.py", line 80, in _run
    self._context.run(self._callback, *self._args)
  File "C:\Users\richa\mpfvirtual4\lib\site-packages\mpf\core\events.py", line 127, in _async_handler_done
    future.result()
  File "C:\Users\richa\mpfvirtual4\lib\site-packages\mpf\core\device_manager.py", line 89, in _load_device_modules
    await self.machine.mode_controller.load_mode_devices()
  File "C:\Users\richa\mpfvirtual4\lib\site-packages\mpf\core\mode_controller.py", line 86, in load_mode_devices
    await mode.load_mode_devices()
  File "C:\Users\richa\mpfvirtual4\lib\site-packages\mpf\core\mode.py", line 438, in load_mode_devices
    settings = device.validate_and_parse_config(settings, True, "mode:" + self.name)
  File "C:\Users\richa\mpfvirtual4\lib\site-packages\mpf\core\device.py", line 108, in validate_and_parse_config
    self.machine.config_validator.validate_config(
  File "C:\Users\richa\mpfvirtual4\lib\site-packages\mpf\core\config_validator.py", line 164, in validate_config
    return self._validate_config(config_spec, source, base_spec=base_spec, add_missing_keys=add_missing_keys,
  File "C:\Users\richa\mpfvirtual4\lib\site-packages\mpf\core\config_validator.py", line 205, in _validate_config
    processed_config[k] = self.validate_config_item(
  File "C:\Users\richa\mpfvirtual4\lib\site-packages\mpf\core\config_validator.py", line 273, in validate_config_item
    return self._validate_dict(item_type, validation, validation_failure_info, item)
  File "C:\Users\richa\mpfvirtual4\lib\site-packages\mpf\core\config_validator.py", line 304, in _validate_dict
    self.validate_item(v, validators[1], ValidationPath(validation_failure_info, k)))
  File "C:\Users\richa\mpfvirtual4\lib\site-packages\mpf\core\config_validator.py", line 685, in validate_item
    return self.validator_list[validator](item, validation_failure_info=validation_failure_info)
  File "C:\Users\richa\mpfvirtual4\lib\site-packages\mpf\core\config_validator.py", line 579, in _validate_type_ms
    self.validation_error(item, validation_failure_info, "Cannot convert value to ms.", 11)
  File "C:\Users\richa\mpfvirtual4\lib\site-packages\mpf\core\config_validator.py", line 700, in validation_error
    raise ConfigFileError("Config validation error: Entry {} = \"{}\" is not valid. {}".format(
mpf.exceptions.config_file_error.ConfigFileError: Config File Error in ConfigValidator: Config validation error: Entry mode:base:shot_groups:rollover_lanes:reset_events:rollover_lanes_lit_complete = "rollover_lanes_lit_complete" is not valid. Cannot convert value to ms. Error Code: CFE-ConfigValidator-11 (https://missionpinball.org/logs)

During handling of the above exception, another exception occurred:

Traceback (most recent call last):
  File "C:\Users\richa\mpfvirtual4\lib\site-packages\mpf\commands\game.py", line 236, in __init__
    self.machine.run()
  File "C:\Users\richa\mpfvirtual4\lib\site-packages\mpf\core\machine.py", line 684, in run
    self._run_loop()
  File "C:\Users\richa\mpfvirtual4\lib\site-packages\mpf\core\machine.py", line 791, in _run_loop
    report_crash(self._exception['exception'], "exception_during_run", self.config)
  File "C:\Users\richa\mpfvirtual4\lib\site-packages\mpf\core\crash_reporter.py", line 236, in report_crash
    response = input("Do you want to report the crash to the MPF team (yes/no/show)? ")
EOFError
