2025-10-03 18:43:58,404 : INFO : root : Loading config.
2025-10-03 18:43:58,409 : INFO : YamlMultifileConfigLoader : Machine config file #1: config.yaml
2025-10-03 18:43:58,409 : WARNING : ConfigProcessor : Config file in cache changed: C:\Users\richa\ttp5\config\config.yaml
2025-10-03 18:43:58,410 : INFO : ConfigProcessor : Loading config from file C:\Users\richa\mpfvirtual4\lib\site-packages\mpf\mpfconfig.yaml.
2025-10-03 18:43:58,425 : INFO : ConfigProcessor : Loading config: C:\Users\richa\mpfvirtual4\lib\site-packages\mpf\mpfconfig.yaml
2025-10-03 18:43:58,426 : INFO : ConfigProcessor : Loading config from file C:\Users\richa\ttp5\config\config.yaml.
2025-10-03 18:43:58,437 : INFO : ConfigProcessor : Loading config: C:\Users\richa\ttp5\config\config.yaml
2025-10-03 18:43:58,437 : INFO : ConfigProcessor : Loading config: C:\Users\richa\ttp5\config\config_ball_devices.yaml
2025-10-03 18:43:58,439 : INFO : ConfigProcessor : Loading config: C:\Users\richa\ttp5\config\config_coils.yaml
2025-10-03 18:43:58,440 : INFO : ConfigProcessor : Loading config: C:\Users\richa\ttp5\config\config_flippers.yaml
2025-10-03 18:43:58,443 : INFO : ConfigProcessor : Loading config: C:\Users\richa\ttp5\config\config_switches.yaml
2025-10-03 18:43:58,446 : INFO : ConfigProcessor : Config file cache created: C:\Users\richa\AppData\Local\Temp\bad76953a596b8c99f832e0e98026c3b.mpf_cache
2025-10-03 18:43:58,531 : INFO : ConfigProcessor : Loading config from cache: C:\Users\richa\AppData\Local\Temp\77a998d318c788df5647a1900cedfc56.mpf_cache
2025-10-03 18:43:58,532 : INFO : ConfigProcessor : Loading config from cache: C:\Users\richa\AppData\Local\Temp\9c8dea79ca4d15ee886340e992e8cb9d.mpf_cache
2025-10-03 18:43:58,532 : INFO : ConfigProcessor : Loading config from cache: C:\Users\richa\AppData\Local\Temp\8ddee2e87a4f178751335e99da00e9c4.mpf_cache
2025-10-03 18:43:58,533 : INFO : ConfigProcessor : Loading config from cache: C:\Users\richa\AppData\Local\Temp\16d594341c3fbe91b1b6d496c05a6fb0.mpf_cache
2025-10-03 18:43:58,534 : INFO : ConfigProcessor : Loading config from cache: C:\Users\richa\AppData\Local\Temp\9ea1b14cb2b1cce5e8bf981a1ff8cfc5.mpf_cache
2025-10-03 18:43:58,535 : INFO : Machine : Mission Pinball Framework Core Engine v0.57.0.dev39
2025-10-03 18:43:58,535 : INFO : Machine : Command line arguments: {'no_load_cache': False, 'create_config_cache': True, 'bcp': True, 'configfile': ['config.yaml'], 'force_assets_load': False, 'jsonlogging': False, 'logfile': 'logs\\2025-10-03-18-43-58-mpf-DESKTOP-RK7BE5M.log', 'pause': False, 'production': False, 'text_ui': True, 'loglevel': 15, 'consoleloglevel': 20, 'force_platform': None, 'syslog_address': None, 'mc_file_name': None, 'no_sound': False}
2025-10-03 18:43:58,535 : INFO : Machine : MPF path: C:\Users\richa\mpfvirtual4\lib\site-packages\mpf
2025-10-03 18:43:58,535 : INFO : Machine : Machine path: C:\Users\richa\ttp5
2025-10-03 18:43:58,535 : INFO : Machine : Platform: win32
2025-10-03 18:43:58,535 : INFO : Machine : Python executable location: C:\Users\richa\mpfvirtual4\Scripts\python.exe
2025-10-03 18:43:58,535 : INFO : Machine : Python version: 3.9.13 (64-bit)
2025-10-03 18:43:58,537 : INFO : Machine : Initializing MPF...
2025-10-03 18:43:58,924 : INFO : EventManager : Event: ======'machine_var_credits_string'====== Args={'value': 'FREE PLAY', 'prev_value': None, 'change': True}
2025-10-03 18:43:58,977 : INFO : EventManager : Event: ======'machine_var_master_volume'====== Args={'value': 0.5, 'prev_value': None, 'change': True}
2025-10-03 18:43:58,977 : INFO : EventManager : Event: ======'machine_var_player1_score'====== Args={'value': 14636, 'prev_value': None, 'change': True}
2025-10-03 18:43:58,977 : INFO : EventManager : Event: ======'machine_var_mpf_version'====== Args={'value': 'Mission Pinball Framework v0.57.0.dev39', 'prev_value': None, 'change': True}
2025-10-03 18:43:58,977 : INFO : EventManager : Event: ======'machine_var_mpf_extended_version'====== Args={'value': 'Mission Pinball Framework v0.57.0.dev39, Config version:6, Show version: 6, BCP version:1.1', 'prev_value': None, 'change': True}
2025-10-03 18:43:58,977 : INFO : EventManager : Event: ======'machine_var_python_version'====== Args={'value': '3.9.13', 'prev_value': None, 'change': True}
2025-10-03 18:43:58,987 : INFO : EventManager : Event: ======'machine_var_platform'====== Args={'value': 'Windows-10-10.0.19045-SP0', 'prev_value': None, 'change': True}
2025-10-03 18:43:58,987 : INFO : EventManager : Event: ======'machine_var_platform_system'====== Args={'value': 'Windows', 'prev_value': None, 'change': True}
2025-10-03 18:43:58,987 : INFO : EventManager : Event: ======'machine_var_platform_release'====== Args={'value': '10', 'prev_value': None, 'change': True}
2025-10-03 18:43:58,987 : INFO : EventManager : Event: ======'machine_var_platform_version'====== Args={'value': '10.0.19045', 'prev_value': None, 'change': True}
2025-10-03 18:43:58,987 : INFO : EventManager : Event: ======'machine_var_platform_machine'====== Args={'value': 'AMD64', 'prev_value': None, 'change': True}
2025-10-03 18:43:58,987 : INFO : EventManager : Event: ======'init_phase_1'====== Args={}
2025-10-03 18:43:58,997 : ERROR : asyncio : Exception in callback EventManager._async_handler_done(<QueuedEvent>)(<Task finishe...dictionary.")>) at C:\Users\richa\mpfvirtual4\lib\site-packages\mpf\core\events.py:124
handle: <Handle EventManager._async_handler_done(<QueuedEvent>)(<Task finishe...dictionary.")>) at C:\Users\richa\mpfvirtual4\lib\site-packages\mpf\core\events.py:124>
Traceback (most recent call last):
  File "C:\Users\richa\AppData\Local\Programs\Python\Python39\lib\asyncio\events.py", line 80, in _run
    self._context.run(self._callback, *self._args)
  File "C:\Users\richa\mpfvirtual4\lib\site-packages\mpf\core\events.py", line 127, in _async_handler_done
    future.result()
  File "C:\Users\richa\mpfvirtual4\lib\site-packages\mpf\core\device_manager.py", line 83, in _load_device_modules
    self.create_devices(collection_name, config)
  File "C:\Users\richa\mpfvirtual4\lib\site-packages\mpf\core\device_manager.py", line 123, in create_devices
    self.raise_config_error("Device {}:'{}' does not have a valid config. Expected a dictionary.".format(
  File "C:\Users\richa\mpfvirtual4\lib\site-packages\mpf\core\logging.py", line 174, in raise_config_error
    raise ConfigFileError(msg, error_no, self.log.name if self.log else "", context, self._url_base) \
mpf.exceptions.config_file_error.ConfigFileError: Config File Error in DeviceManager: Device lights:'l_left_standup' does not have a valid config. Expected a dictionary. Context: lights.l_left_standup Error Code: CFE-DeviceManager-3 (https://missionpinball.org/logs)
2025-10-03 18:43:59,010 : INFO : Machine : Starting the main run loop.
2025-10-03 18:43:59,016 : INFO : Machine : Shutting down...
2025-10-03 18:43:59,017 : INFO : EventManager : Event: ======'shutdown'====== Args={}
2025-10-03 18:44:00,030 : ERROR : Machine : Runtime Exception
Traceback (most recent call last):
  File "C:\Users\richa\mpfvirtual4\lib\site-packages\mpf\core\machine.py", line 788, in _run_loop
    raise self._exception['exception']
  File "C:\Users\richa\AppData\Local\Programs\Python\Python39\lib\asyncio\events.py", line 80, in _run
    self._context.run(self._callback, *self._args)
  File "C:\Users\richa\mpfvirtual4\lib\site-packages\mpf\core\events.py", line 127, in _async_handler_done
    future.result()
  File "C:\Users\richa\mpfvirtual4\lib\site-packages\mpf\core\device_manager.py", line 83, in _load_device_modules
    self.create_devices(collection_name, config)
  File "C:\Users\richa\mpfvirtual4\lib\site-packages\mpf\core\device_manager.py", line 123, in create_devices
    self.raise_config_error("Device {}:'{}' does not have a valid config. Expected a dictionary.".format(
  File "C:\Users\richa\mpfvirtual4\lib\site-packages\mpf\core\logging.py", line 174, in raise_config_error
    raise ConfigFileError(msg, error_no, self.log.name if self.log else "", context, self._url_base) \
mpf.exceptions.config_file_error.ConfigFileError: Config File Error in DeviceManager: Device lights:'l_left_standup' does not have a valid config. Expected a dictionary. Context: lights.l_left_standup Error Code: CFE-DeviceManager-3 (https://missionpinball.org/logs)
2025-10-03 18:44:50,112 : ERROR : root : 
Traceback (most recent call last):
  File "C:\Users\richa\mpfvirtual4\lib\site-packages\mpf\core\machine.py", line 788, in _run_loop
    raise self._exception['exception']
  File "C:\Users\richa\AppData\Local\Programs\Python\Python39\lib\asyncio\events.py", line 80, in _run
    self._context.run(self._callback, *self._args)
  File "C:\Users\richa\mpfvirtual4\lib\site-packages\mpf\core\events.py", line 127, in _async_handler_done
    future.result()
  File "C:\Users\richa\mpfvirtual4\lib\site-packages\mpf\core\device_manager.py", line 83, in _load_device_modules
    self.create_devices(collection_name, config)
  File "C:\Users\richa\mpfvirtual4\lib\site-packages\mpf\core\device_manager.py", line 123, in create_devices
    self.raise_config_error("Device {}:'{}' does not have a valid config. Expected a dictionary.".format(
  File "C:\Users\richa\mpfvirtual4\lib\site-packages\mpf\core\logging.py", line 174, in raise_config_error
    raise ConfigFileError(msg, error_no, self.log.name if self.log else "", context, self._url_base) \
mpf.exceptions.config_file_error.ConfigFileError: Config File Error in DeviceManager: Device lights:'l_left_standup' does not have a valid config. Expected a dictionary. Context: lights.l_left_standup Error Code: CFE-DeviceManager-3 (https://missionpinball.org/logs)

During handling of the above exception, another exception occurred:

Traceback (most recent call last):
  File "C:\Users\richa\mpfvirtual4\lib\site-packages\mpf\commands\game.py", line 236, in __init__
    self.machine.run()
  File "C:\Users\richa\mpfvirtual4\lib\site-packages\mpf\core\machine.py", line 684, in run
    self._run_loop()
  File "C:\Users\richa\mpfvirtual4\lib\site-packages\mpf\core\machine.py", line 791, in _run_loop
    report_crash(self._exception['exception'], "exception_during_run", self.config)
  File "C:\Users\richa\mpfvirtual4\lib\site-packages\mpf\core\crash_reporter.py", line 236, in report_crash
    response = input("Do you want to report the crash to the MPF team (yes/no/show)? ")
EOFError
