2025-10-04 08:31:16,759 : INFO : root : Loading config.
2025-10-04 08:31:16,763 : INFO : YamlMultifileConfigLoader : Machine config file #1: config.yaml
2025-10-04 08:31:16,764 : INFO : ConfigProcessor : Loading config from cache: C:\Users\richa\AppData\Local\Temp\bad76953a596b8c99f832e0e98026c3b.mpf_cache
2025-10-04 08:31:16,853 : INFO : ConfigProcessor : Loading config from cache: C:\Users\richa\AppData\Local\Temp\77a998d318c788df5647a1900cedfc56.mpf_cache
2025-10-04 08:31:16,853 : INFO : ConfigProcessor : Loading config from cache: C:\Users\richa\AppData\Local\Temp\9c8dea79ca4d15ee886340e992e8cb9d.mpf_cache
2025-10-04 08:31:16,854 : INFO : ConfigProcessor : Loading config from cache: C:\Users\richa\AppData\Local\Temp\8ddee2e87a4f178751335e99da00e9c4.mpf_cache
2025-10-04 08:31:16,855 : INFO : ConfigProcessor : Loading config from cache: C:\Users\richa\AppData\Local\Temp\16d594341c3fbe91b1b6d496c05a6fb0.mpf_cache
2025-10-04 08:31:16,856 : INFO : ConfigProcessor : Loading config from cache: C:\Users\richa\AppData\Local\Temp\9ea1b14cb2b1cce5e8bf981a1ff8cfc5.mpf_cache
2025-10-04 08:31:16,856 : INFO : Machine : Mission Pinball Framework Core Engine v0.57.0.dev39
2025-10-04 08:31:16,856 : INFO : Machine : Command line arguments: {'no_load_cache': False, 'create_config_cache': True, 'bcp': True, 'configfile': ['config.yaml'], 'force_assets_load': False, 'jsonlogging': False, 'logfile': 'logs\\2025-10-04-08-31-16-mpf-DESKTOP-RK7BE5M.log', 'pause': False, 'production': False, 'text_ui': True, 'loglevel': 15, 'consoleloglevel': 20, 'force_platform': None, 'syslog_address': None, 'mc_file_name': None, 'no_sound': False}
2025-10-04 08:31:16,857 : INFO : Machine : MPF path: C:\Users\richa\mpfvirtual4\lib\site-packages\mpf
2025-10-04 08:31:16,857 : INFO : Machine : Machine path: C:\Users\richa\ttp5
2025-10-04 08:31:16,857 : INFO : Machine : Platform: win32
2025-10-04 08:31:16,857 : INFO : Machine : Python executable location: C:\Users\richa\mpfvirtual4\Scripts\python.exe
2025-10-04 08:31:16,857 : INFO : Machine : Python version: 3.9.13 (64-bit)
2025-10-04 08:31:16,858 : INFO : Machine : Initializing MPF...
2025-10-04 08:31:17,379 : INFO : EventManager : Event: ======'machine_var_credits_string'====== Args={'value': 'FREE PLAY', 'prev_value': None, 'change': True}
2025-10-04 08:31:17,439 : INFO : EventManager : Event: ======'machine_var_master_volume'====== Args={'value': 0.5, 'prev_value': None, 'change': True}
2025-10-04 08:31:17,439 : INFO : EventManager : Event: ======'machine_var_player1_score'====== Args={'value': 11909, 'prev_value': None, 'change': True}
2025-10-04 08:31:17,440 : INFO : EventManager : Event: ======'machine_var_mpf_version'====== Args={'value': 'Mission Pinball Framework v0.57.0.dev39', 'prev_value': None, 'change': True}
2025-10-04 08:31:17,440 : INFO : EventManager : Event: ======'machine_var_mpf_extended_version'====== Args={'value': 'Mission Pinball Framework v0.57.0.dev39, Config version:6, Show version: 6, BCP version:1.1', 'prev_value': None, 'change': True}
2025-10-04 08:31:17,440 : INFO : EventManager : Event: ======'machine_var_python_version'====== Args={'value': '3.9.13', 'prev_value': None, 'change': True}
2025-10-04 08:31:17,449 : INFO : EventManager : Event: ======'machine_var_platform'====== Args={'value': 'Windows-10-10.0.19045-SP0', 'prev_value': None, 'change': True}
2025-10-04 08:31:17,449 : INFO : EventManager : Event: ======'machine_var_platform_system'====== Args={'value': 'Windows', 'prev_value': None, 'change': True}
2025-10-04 08:31:17,449 : INFO : EventManager : Event: ======'machine_var_platform_release'====== Args={'value': '10', 'prev_value': None, 'change': True}
2025-10-04 08:31:17,449 : INFO : EventManager : Event: ======'machine_var_platform_version'====== Args={'value': '10.0.19045', 'prev_value': None, 'change': True}
2025-10-04 08:31:17,449 : INFO : EventManager : Event: ======'machine_var_platform_machine'====== Args={'value': 'AMD64', 'prev_value': None, 'change': True}
2025-10-04 08:31:17,449 : INFO : EventManager : Event: ======'init_phase_1'====== Args={}
2025-10-04 08:31:17,466 : ERROR : asyncio : Exception in callback EventManager._async_handler_done(<QueuedEvent>)(<Task finishe...our config.')>) at C:\Users\richa\mpfvirtual4\lib\site-packages\mpf\core\events.py:124
handle: <Handle EventManager._async_handler_done(<QueuedEvent>)(<Task finishe...our config.')>) at C:\Users\richa\mpfvirtual4\lib\site-packages\mpf\core\events.py:124>
Traceback (most recent call last):
  File "C:\Users\richa\AppData\Local\Programs\Python\Python39\lib\asyncio\events.py", line 80, in _run
    self._context.run(self._callback, *self._args)
  File "C:\Users\richa\mpfvirtual4\lib\site-packages\mpf\core\events.py", line 127, in _async_handler_done
    future.result()
  File "C:\Users\richa\mpfvirtual4\lib\site-packages\mpf\core\device_manager.py", line 89, in _load_device_modules
    await self.machine.mode_controller.load_mode_devices()
  File "C:\Users\richa\mpfvirtual4\lib\site-packages\mpf\core\mode_controller.py", line 86, in load_mode_devices
    await mode.load_mode_devices()
  File "C:\Users\richa\mpfvirtual4\lib\site-packages\mpf\core\mode.py", line 438, in load_mode_devices
    settings = device.validate_and_parse_config(settings, True, "mode:" + self.name)
  File "C:\Users\richa\mpfvirtual4\lib\site-packages\mpf\devices\shot.py", line 72, in validate_and_parse_config
    config = super().validate_and_parse_config(config, is_mode_config, debug_prefix)
  File "C:\Users\richa\mpfvirtual4\lib\site-packages\mpf\core\device.py", line 108, in validate_and_parse_config
    self.machine.config_validator.validate_config(
  File "C:\Users\richa\mpfvirtual4\lib\site-packages\mpf\core\config_validator.py", line 164, in validate_config
    return self._validate_config(config_spec, source, base_spec=base_spec, add_missing_keys=add_missing_keys,
  File "C:\Users\richa\mpfvirtual4\lib\site-packages\mpf\core\config_validator.py", line 205, in _validate_config
    processed_config[k] = self.validate_config_item(
  File "C:\Users\richa\mpfvirtual4\lib\site-packages\mpf\core\config_validator.py", line 257, in validate_config_item
    new_list.append(self.validate_item(i, validation, validation_failure_info))
  File "C:\Users\richa\mpfvirtual4\lib\site-packages\mpf\core\config_validator.py", line 683, in validate_item
    return self.validator_list[validator](item, validation_failure_info=validation_failure_info, param=param)
  File "C:\Users\richa\mpfvirtual4\lib\site-packages\mpf\core\config_validator.py", line 401, in _validate_type_machine
    return self.validation_error(item, validation_failure_info,
  File "C:\Users\richa\mpfvirtual4\lib\site-packages\mpf\core\config_validator.py", line 700, in validation_error
    raise ConfigFileError("Config validation error: Entry {} = \"{}\" is not valid. {}".format(
mpf.exceptions.config_file_error.ConfigFileError: Config File Error in ConfigValidator: Config validation error: Entry mode:base:shots:left_rollover:switch = "left_rollover" is not valid. Device "left_rollover" not found in "switches:" section in your config. Error Code: CFE-ConfigValidator-6 (https://missionpinball.org/logs)
2025-10-04 08:31:17,469 : INFO : Machine : Starting the main run loop.
2025-10-04 08:31:17,477 : INFO : Machine : Shutting down...
2025-10-04 08:31:17,478 : INFO : EventManager : Event: ======'shutdown'====== Args={}
2025-10-04 08:31:18,496 : ERROR : Machine : Runtime Exception
Traceback (most recent call last):
  File "C:\Users\richa\mpfvirtual4\lib\site-packages\mpf\core\machine.py", line 788, in _run_loop
    raise self._exception['exception']
  File "C:\Users\richa\AppData\Local\Programs\Python\Python39\lib\asyncio\events.py", line 80, in _run
    self._context.run(self._callback, *self._args)
  File "C:\Users\richa\mpfvirtual4\lib\site-packages\mpf\core\events.py", line 127, in _async_handler_done
    future.result()
  File "C:\Users\richa\mpfvirtual4\lib\site-packages\mpf\core\device_manager.py", line 89, in _load_device_modules
    await self.machine.mode_controller.load_mode_devices()
  File "C:\Users\richa\mpfvirtual4\lib\site-packages\mpf\core\mode_controller.py", line 86, in load_mode_devices
    await mode.load_mode_devices()
  File "C:\Users\richa\mpfvirtual4\lib\site-packages\mpf\core\mode.py", line 438, in load_mode_devices
    settings = device.validate_and_parse_config(settings, True, "mode:" + self.name)
  File "C:\Users\richa\mpfvirtual4\lib\site-packages\mpf\devices\shot.py", line 72, in validate_and_parse_config
    config = super().validate_and_parse_config(config, is_mode_config, debug_prefix)
  File "C:\Users\richa\mpfvirtual4\lib\site-packages\mpf\core\device.py", line 108, in validate_and_parse_config
    self.machine.config_validator.validate_config(
  File "C:\Users\richa\mpfvirtual4\lib\site-packages\mpf\core\config_validator.py", line 164, in validate_config
    return self._validate_config(config_spec, source, base_spec=base_spec, add_missing_keys=add_missing_keys,
  File "C:\Users\richa\mpfvirtual4\lib\site-packages\mpf\core\config_validator.py", line 205, in _validate_config
    processed_config[k] = self.validate_config_item(
  File "C:\Users\richa\mpfvirtual4\lib\site-packages\mpf\core\config_validator.py", line 257, in validate_config_item
    new_list.append(self.validate_item(i, validation, validation_failure_info))
  File "C:\Users\richa\mpfvirtual4\lib\site-packages\mpf\core\config_validator.py", line 683, in validate_item
    return self.validator_list[validator](item, validation_failure_info=validation_failure_info, param=param)
  File "C:\Users\richa\mpfvirtual4\lib\site-packages\mpf\core\config_validator.py", line 401, in _validate_type_machine
    return self.validation_error(item, validation_failure_info,
  File "C:\Users\richa\mpfvirtual4\lib\site-packages\mpf\core\config_validator.py", line 700, in validation_error
    raise ConfigFileError("Config validation error: Entry {} = \"{}\" is not valid. {}".format(
mpf.exceptions.config_file_error.ConfigFileError: Config File Error in ConfigValidator: Config validation error: Entry mode:base:shots:left_rollover:switch = "left_rollover" is not valid. Device "left_rollover" not found in "switches:" section in your config. Error Code: CFE-ConfigValidator-6 (https://missionpinball.org/logs)
2025-10-04 08:31:22,921 : ERROR : root : 
Traceback (most recent call last):
  File "C:\Users\richa\mpfvirtual4\lib\site-packages\mpf\core\machine.py", line 788, in _run_loop
    raise self._exception['exception']
  File "C:\Users\richa\AppData\Local\Programs\Python\Python39\lib\asyncio\events.py", line 80, in _run
    self._context.run(self._callback, *self._args)
  File "C:\Users\richa\mpfvirtual4\lib\site-packages\mpf\core\events.py", line 127, in _async_handler_done
    future.result()
  File "C:\Users\richa\mpfvirtual4\lib\site-packages\mpf\core\device_manager.py", line 89, in _load_device_modules
    await self.machine.mode_controller.load_mode_devices()
  File "C:\Users\richa\mpfvirtual4\lib\site-packages\mpf\core\mode_controller.py", line 86, in load_mode_devices
    await mode.load_mode_devices()
  File "C:\Users\richa\mpfvirtual4\lib\site-packages\mpf\core\mode.py", line 438, in load_mode_devices
    settings = device.validate_and_parse_config(settings, True, "mode:" + self.name)
  File "C:\Users\richa\mpfvirtual4\lib\site-packages\mpf\devices\shot.py", line 72, in validate_and_parse_config
    config = super().validate_and_parse_config(config, is_mode_config, debug_prefix)
  File "C:\Users\richa\mpfvirtual4\lib\site-packages\mpf\core\device.py", line 108, in validate_and_parse_config
    self.machine.config_validator.validate_config(
  File "C:\Users\richa\mpfvirtual4\lib\site-packages\mpf\core\config_validator.py", line 164, in validate_config
    return self._validate_config(config_spec, source, base_spec=base_spec, add_missing_keys=add_missing_keys,
  File "C:\Users\richa\mpfvirtual4\lib\site-packages\mpf\core\config_validator.py", line 205, in _validate_config
    processed_config[k] = self.validate_config_item(
  File "C:\Users\richa\mpfvirtual4\lib\site-packages\mpf\core\config_validator.py", line 257, in validate_config_item
    new_list.append(self.validate_item(i, validation, validation_failure_info))
  File "C:\Users\richa\mpfvirtual4\lib\site-packages\mpf\core\config_validator.py", line 683, in validate_item
    return self.validator_list[validator](item, validation_failure_info=validation_failure_info, param=param)
  File "C:\Users\richa\mpfvirtual4\lib\site-packages\mpf\core\config_validator.py", line 401, in _validate_type_machine
    return self.validation_error(item, validation_failure_info,
  File "C:\Users\richa\mpfvirtual4\lib\site-packages\mpf\core\config_validator.py", line 700, in validation_error
    raise ConfigFileError("Config validation error: Entry {} = \"{}\" is not valid. {}".format(
mpf.exceptions.config_file_error.ConfigFileError: Config File Error in ConfigValidator: Config validation error: Entry mode:base:shots:left_rollover:switch = "left_rollover" is not valid. Device "left_rollover" not found in "switches:" section in your config. Error Code: CFE-ConfigValidator-6 (https://missionpinball.org/logs)

During handling of the above exception, another exception occurred:

Traceback (most recent call last):
  File "C:\Users\richa\mpfvirtual4\lib\site-packages\mpf\commands\game.py", line 236, in __init__
    self.machine.run()
  File "C:\Users\richa\mpfvirtual4\lib\site-packages\mpf\core\machine.py", line 684, in run
    self._run_loop()
  File "C:\Users\richa\mpfvirtual4\lib\site-packages\mpf\core\machine.py", line 791, in _run_loop
    report_crash(self._exception['exception'], "exception_during_run", self.config)
  File "C:\Users\richa\mpfvirtual4\lib\site-packages\mpf\core\crash_reporter.py", line 236, in report_crash
    response = input("Do you want to report the crash to the MPF team (yes/no/show)? ")
EOFError
